2020-06-21 14:27:10,638 - Logging.py[line:43] - DEBUG: 这是 logger debug message
2020-06-21 14:27:10,638 - Logging.py[line:44] - INFO: ------------------------------
2020-06-21 14:27:10,639 - Logging.py[line:45] - INFO: 这是 logger info message
2020-06-21 14:27:10,639 - Logging.py[line:46] - WARNING: 这是 logger warning message
2020-06-21 14:27:10,639 - Logging.py[line:47] - ERROR: 这是 logger error message
2020-06-21 14:27:10,639 - Logging.py[line:48] - CRITICAL: 这是 logger critical message
2020-06-21 17:06:18,629 - autoreload.py[line:203] - INFO: D:\Django_today\my_fresh\apps\users\views.py changed, reloading.
2020-06-21 17:17:26,298 - autoreload.py[line:203] - INFO: D:\Django_today\my_fresh\apps\users\views.py changed, reloading.
2020-06-21 17:17:26,298 - autoreload.py[line:203] - INFO: D:\Django_today\my_fresh\apps\users\views.py changed, reloading.
2020-06-21 17:21:30,497 - autoreload.py[line:203] - INFO: D:\Django_today\my_fresh\apps\users\views.py changed, reloading.
2020-06-21 17:22:02,823 - log.py[line:222] - ERROR: Internal Server Error: /users/register
Traceback (most recent call last):
  File "C:\Users\Administrator\Envs\django_today\lib\site-packages\django\core\handlers\exception.py", line 34, in inner
    response = get_response(request)
  File "C:\Users\Administrator\Envs\django_today\lib\site-packages\django\core\handlers\base.py", line 115, in _get_response
    response = self.process_exception_by_middleware(e, request)
  File "C:\Users\Administrator\Envs\django_today\lib\site-packages\django\core\handlers\base.py", line 113, in _get_response
    response = wrapped_callback(request, *callback_args, **callback_kwargs)
  File "D:\Django_today\my_fresh\apps\users\views.py", line 88, in register
    send_mail(subject, message, sender, receiver, html_message=html_message)
  File "C:\Users\Administrator\Envs\django_today\lib\site-packages\django\core\mail\__init__.py", line 60, in send_mail
    return mail.send()
  File "C:\Users\Administrator\Envs\django_today\lib\site-packages\django\core\mail\message.py", line 291, in send
    return self.get_connection(fail_silently).send_messages([self])
  File "C:\Users\Administrator\Envs\django_today\lib\site-packages\django\core\mail\backends\smtp.py", line 103, in send_messages
    new_conn_created = self.open()
  File "C:\Users\Administrator\Envs\django_today\lib\site-packages\django\core\mail\backends\smtp.py", line 70, in open
    self.connection.login(self.username, self.password)
  File "c:\users\administrator\appdata\local\programs\python\python38-32\Lib\smtplib.py", line 734, in login
    raise last_exception
  File "c:\users\administrator\appdata\local\programs\python\python38-32\Lib\smtplib.py", line 723, in login
    (code, resp) = self.auth(
  File "c:\users\administrator\appdata\local\programs\python\python38-32\Lib\smtplib.py", line 646, in auth
    raise SMTPAuthenticationError(code, resp)
smtplib.SMTPAuthenticationError: (535, b'Login fail. Authorization code is expired')
2020-06-21 17:22:02,823 - log.py[line:222] - ERROR: Internal Server Error: /users/register
Traceback (most recent call last):
  File "C:\Users\Administrator\Envs\django_today\lib\site-packages\django\core\handlers\exception.py", line 34, in inner
    response = get_response(request)
  File "C:\Users\Administrator\Envs\django_today\lib\site-packages\django\core\handlers\base.py", line 115, in _get_response
    response = self.process_exception_by_middleware(e, request)
  File "C:\Users\Administrator\Envs\django_today\lib\site-packages\django\core\handlers\base.py", line 113, in _get_response
    response = wrapped_callback(request, *callback_args, **callback_kwargs)
  File "D:\Django_today\my_fresh\apps\users\views.py", line 88, in register
    send_mail(subject, message, sender, receiver, html_message=html_message)
  File "C:\Users\Administrator\Envs\django_today\lib\site-packages\django\core\mail\__init__.py", line 60, in send_mail
    return mail.send()
  File "C:\Users\Administrator\Envs\django_today\lib\site-packages\django\core\mail\message.py", line 291, in send
    return self.get_connection(fail_silently).send_messages([self])
  File "C:\Users\Administrator\Envs\django_today\lib\site-packages\django\core\mail\backends\smtp.py", line 103, in send_messages
    new_conn_created = self.open()
  File "C:\Users\Administrator\Envs\django_today\lib\site-packages\django\core\mail\backends\smtp.py", line 70, in open
    self.connection.login(self.username, self.password)
  File "c:\users\administrator\appdata\local\programs\python\python38-32\Lib\smtplib.py", line 734, in login
    raise last_exception
  File "c:\users\administrator\appdata\local\programs\python\python38-32\Lib\smtplib.py", line 723, in login
    (code, resp) = self.auth(
  File "c:\users\administrator\appdata\local\programs\python\python38-32\Lib\smtplib.py", line 646, in auth
    raise SMTPAuthenticationError(code, resp)
smtplib.SMTPAuthenticationError: (535, b'Login fail. Authorization code is expired')
2020-06-21 17:39:24,334 - log.py[line:222] - ERROR: Internal Server Error: /users/active/eyJhbGciOiJIUzUxMiIsImlhdCI6MTU5MjczMjM1OSwiZXhwIjoxNTkyNzM1OTU5fQ.eyJjb25maXJtIjo3fQ.nFrHoU-bYzOdC4BaYkXPdqr3vIma1vcxFF1AFudZjpmHkREwWdBn9OcdlpEiztFM3IR43Tq3_QUozpVD54IjTA
Traceback (most recent call last):
  File "C:\Users\Administrator\Envs\django_today\lib\site-packages\django\core\handlers\exception.py", line 34, in inner
    response = get_response(request)
  File "C:\Users\Administrator\Envs\django_today\lib\site-packages\django\core\handlers\base.py", line 115, in _get_response
    response = self.process_exception_by_middleware(e, request)
  File "C:\Users\Administrator\Envs\django_today\lib\site-packages\django\core\handlers\base.py", line 113, in _get_response
    response = wrapped_callback(request, *callback_args, **callback_kwargs)
  File "C:\Users\Administrator\Envs\django_today\lib\site-packages\django\views\generic\base.py", line 71, in view
    return self.dispatch(request, *args, **kwargs)
  File "C:\Users\Administrator\Envs\django_today\lib\site-packages\django\views\generic\base.py", line 97, in dispatch
    return handler(request, *args, **kwargs)
TypeError: get() missing 1 required positional argument: 'token'
2020-06-21 17:39:24,334 - log.py[line:222] - ERROR: Internal Server Error: /users/active/eyJhbGciOiJIUzUxMiIsImlhdCI6MTU5MjczMjM1OSwiZXhwIjoxNTkyNzM1OTU5fQ.eyJjb25maXJtIjo3fQ.nFrHoU-bYzOdC4BaYkXPdqr3vIma1vcxFF1AFudZjpmHkREwWdBn9OcdlpEiztFM3IR43Tq3_QUozpVD54IjTA
Traceback (most recent call last):
  File "C:\Users\Administrator\Envs\django_today\lib\site-packages\django\core\handlers\exception.py", line 34, in inner
    response = get_response(request)
  File "C:\Users\Administrator\Envs\django_today\lib\site-packages\django\core\handlers\base.py", line 115, in _get_response
    response = self.process_exception_by_middleware(e, request)
  File "C:\Users\Administrator\Envs\django_today\lib\site-packages\django\core\handlers\base.py", line 113, in _get_response
    response = wrapped_callback(request, *callback_args, **callback_kwargs)
  File "C:\Users\Administrator\Envs\django_today\lib\site-packages\django\views\generic\base.py", line 71, in view
    return self.dispatch(request, *args, **kwargs)
  File "C:\Users\Administrator\Envs\django_today\lib\site-packages\django\views\generic\base.py", line 97, in dispatch
    return handler(request, *args, **kwargs)
TypeError: get() missing 1 required positional argument: 'token'
2020-06-21 18:34:34,754 - autoreload.py[line:203] - INFO: D:\Django_today\my_fresh\apps\users\views.py changed, reloading.
2020-06-22 02:51:44,502 - log.py[line:222] - ERROR: Internal Server Error: /users/info
Traceback (most recent call last):
  File "C:\Users\Administrator\Envs\django_today\lib\site-packages\django\core\handlers\exception.py", line 34, in inner
    response = get_response(request)
  File "C:\Users\Administrator\Envs\django_today\lib\site-packages\django\core\handlers\base.py", line 115, in _get_response
    response = self.process_exception_by_middleware(e, request)
  File "C:\Users\Administrator\Envs\django_today\lib\site-packages\django\core\handlers\base.py", line 113, in _get_response
    response = wrapped_callback(request, *callback_args, **callback_kwargs)
  File "C:\Users\Administrator\Envs\django_today\lib\site-packages\django\views\generic\base.py", line 71, in view
    return self.dispatch(request, *args, **kwargs)
  File "C:\Users\Administrator\Envs\django_today\lib\site-packages\django\views\generic\base.py", line 97, in dispatch
    return handler(request, *args, **kwargs)
  File "D:\Django_today\my_fresh\apps\users\views.py", line 200, in get
    return render(request, 'user_center_info.html')
  File "C:\Users\Administrator\Envs\django_today\lib\site-packages\django\shortcuts.py", line 36, in render
    content = loader.render_to_string(template_name, context, request, using=using)
  File "C:\Users\Administrator\Envs\django_today\lib\site-packages\django\template\loader.py", line 62, in render_to_string
    return template.render(context, request)
  File "C:\Users\Administrator\Envs\django_today\lib\site-packages\django\template\backends\django.py", line 61, in render
    return self.template.render(context)
  File "C:\Users\Administrator\Envs\django_today\lib\site-packages\django\template\base.py", line 171, in render
    return self._render(context)
  File "C:\Users\Administrator\Envs\django_today\lib\site-packages\django\template\base.py", line 163, in _render
    return self.nodelist.render(context)
  File "C:\Users\Administrator\Envs\django_today\lib\site-packages\django\template\base.py", line 937, in render
    bit = node.render_annotated(context)
  File "C:\Users\Administrator\Envs\django_today\lib\site-packages\django\template\base.py", line 904, in render_annotated
    return self.render(context)
  File "C:\Users\Administrator\Envs\django_today\lib\site-packages\django\template\loader_tags.py", line 150, in render
    return compiled_parent._render(context)
  File "C:\Users\Administrator\Envs\django_today\lib\site-packages\django\template\base.py", line 163, in _render
    return self.nodelist.render(context)
  File "C:\Users\Administrator\Envs\django_today\lib\site-packages\django\template\base.py", line 937, in render
    bit = node.render_annotated(context)
  File "C:\Users\Administrator\Envs\django_today\lib\site-packages\django\template\base.py", line 904, in render_annotated
    return self.render(context)
  File "C:\Users\Administrator\Envs\django_today\lib\site-packages\django\template\loader_tags.py", line 150, in render
    return compiled_parent._render(context)
  File "C:\Users\Administrator\Envs\django_today\lib\site-packages\django\template\base.py", line 163, in _render
    return self.nodelist.render(context)
  File "C:\Users\Administrator\Envs\django_today\lib\site-packages\django\template\base.py", line 937, in render
    bit = node.render_annotated(context)
  File "C:\Users\Administrator\Envs\django_today\lib\site-packages\django\template\base.py", line 904, in render_annotated
    return self.render(context)
  File "C:\Users\Administrator\Envs\django_today\lib\site-packages\django\template\loader_tags.py", line 150, in render
    return compiled_parent._render(context)
  File "C:\Users\Administrator\Envs\django_today\lib\site-packages\django\template\base.py", line 163, in _render
    return self.nodelist.render(context)
  File "C:\Users\Administrator\Envs\django_today\lib\site-packages\django\template\base.py", line 937, in render
    bit = node.render_annotated(context)
  File "C:\Users\Administrator\Envs\django_today\lib\site-packages\django\template\base.py", line 904, in render_annotated
    return self.render(context)
  File "C:\Users\Administrator\Envs\django_today\lib\site-packages\django\template\loader_tags.py", line 62, in render
    result = block.nodelist.render(context)
  File "C:\Users\Administrator\Envs\django_today\lib\site-packages\django\template\base.py", line 937, in render
    bit = node.render_annotated(context)
  File "C:\Users\Administrator\Envs\django_today\lib\site-packages\django\template\base.py", line 904, in render_annotated
    return self.render(context)
  File "C:\Users\Administrator\Envs\django_today\lib\site-packages\django\template\defaulttags.py", line 443, in render
    url = reverse(view_name, args=args, kwargs=kwargs, current_app=current_app)
  File "C:\Users\Administrator\Envs\django_today\lib\site-packages\django\urls\base.py", line 90, in reverse
    return iri_to_uri(resolver._reverse_with_prefix(view, prefix, *args, **kwargs))
  File "C:\Users\Administrator\Envs\django_today\lib\site-packages\django\urls\resolvers.py", line 668, in _reverse_with_prefix
    raise NoReverseMatch(msg)
django.urls.exceptions.NoReverseMatch: Reverse for 'user' not found. 'user' is not a valid view function or pattern name.
2020-06-22 02:51:45,587 - log.py[line:222] - ERROR: Internal Server Error: /users/order
Traceback (most recent call last):
  File "C:\Users\Administrator\Envs\django_today\lib\site-packages\django\core\handlers\exception.py", line 34, in inner
    response = get_response(request)
  File "C:\Users\Administrator\Envs\django_today\lib\site-packages\django\core\handlers\base.py", line 115, in _get_response
    response = self.process_exception_by_middleware(e, request)
  File "C:\Users\Administrator\Envs\django_today\lib\site-packages\django\core\handlers\base.py", line 113, in _get_response
    response = wrapped_callback(request, *callback_args, **callback_kwargs)
  File "C:\Users\Administrator\Envs\django_today\lib\site-packages\django\views\generic\base.py", line 71, in view
    return self.dispatch(request, *args, **kwargs)
  File "C:\Users\Administrator\Envs\django_today\lib\site-packages\django\views\generic\base.py", line 97, in dispatch
    return handler(request, *args, **kwargs)
  File "D:\Django_today\my_fresh\apps\users\views.py", line 206, in get
    return render(request, "user_center_order.html")
  File "C:\Users\Administrator\Envs\django_today\lib\site-packages\django\shortcuts.py", line 36, in render
    content = loader.render_to_string(template_name, context, request, using=using)
  File "C:\Users\Administrator\Envs\django_today\lib\site-packages\django\template\loader.py", line 62, in render_to_string
    return template.render(context, request)
  File "C:\Users\Administrator\Envs\django_today\lib\site-packages\django\template\backends\django.py", line 61, in render
    return self.template.render(context)
  File "C:\Users\Administrator\Envs\django_today\lib\site-packages\django\template\base.py", line 171, in render
    return self._render(context)
  File "C:\Users\Administrator\Envs\django_today\lib\site-packages\django\template\base.py", line 163, in _render
    return self.nodelist.render(context)
  File "C:\Users\Administrator\Envs\django_today\lib\site-packages\django\template\base.py", line 937, in render
    bit = node.render_annotated(context)
  File "C:\Users\Administrator\Envs\django_today\lib\site-packages\django\template\base.py", line 904, in render_annotated
    return self.render(context)
  File "C:\Users\Administrator\Envs\django_today\lib\site-packages\django\template\loader_tags.py", line 150, in render
    return compiled_parent._render(context)
  File "C:\Users\Administrator\Envs\django_today\lib\site-packages\django\template\base.py", line 163, in _render
    return self.nodelist.render(context)
  File "C:\Users\Administrator\Envs\django_today\lib\site-packages\django\template\base.py", line 937, in render
    bit = node.render_annotated(context)
  File "C:\Users\Administrator\Envs\django_today\lib\site-packages\django\template\base.py", line 904, in render_annotated
    return self.render(context)
  File "C:\Users\Administrator\Envs\django_today\lib\site-packages\django\template\loader_tags.py", line 150, in render
    return compiled_parent._render(context)
  File "C:\Users\Administrator\Envs\django_today\lib\site-packages\django\template\base.py", line 163, in _render
    return self.nodelist.render(context)
  File "C:\Users\Administrator\Envs\django_today\lib\site-packages\django\template\base.py", line 937, in render
    bit = node.render_annotated(context)
  File "C:\Users\Administrator\Envs\django_today\lib\site-packages\django\template\base.py", line 904, in render_annotated
    return self.render(context)
  File "C:\Users\Administrator\Envs\django_today\lib\site-packages\django\template\loader_tags.py", line 150, in render
    return compiled_parent._render(context)
  File "C:\Users\Administrator\Envs\django_today\lib\site-packages\django\template\base.py", line 163, in _render
    return self.nodelist.render(context)
  File "C:\Users\Administrator\Envs\django_today\lib\site-packages\django\template\base.py", line 937, in render
    bit = node.render_annotated(context)
  File "C:\Users\Administrator\Envs\django_today\lib\site-packages\django\template\base.py", line 904, in render_annotated
    return self.render(context)
  File "C:\Users\Administrator\Envs\django_today\lib\site-packages\django\template\loader_tags.py", line 62, in render
    result = block.nodelist.render(context)
  File "C:\Users\Administrator\Envs\django_today\lib\site-packages\django\template\base.py", line 937, in render
    bit = node.render_annotated(context)
  File "C:\Users\Administrator\Envs\django_today\lib\site-packages\django\template\base.py", line 904, in render_annotated
    return self.render(context)
  File "C:\Users\Administrator\Envs\django_today\lib\site-packages\django\template\defaulttags.py", line 443, in render
    url = reverse(view_name, args=args, kwargs=kwargs, current_app=current_app)
  File "C:\Users\Administrator\Envs\django_today\lib\site-packages\django\urls\base.py", line 90, in reverse
    return iri_to_uri(resolver._reverse_with_prefix(view, prefix, *args, **kwargs))
  File "C:\Users\Administrator\Envs\django_today\lib\site-packages\django\urls\resolvers.py", line 668, in _reverse_with_prefix
    raise NoReverseMatch(msg)
django.urls.exceptions.NoReverseMatch: Reverse for 'user' not found. 'user' is not a valid view function or pattern name.
2020-06-22 02:51:46,593 - log.py[line:222] - ERROR: Internal Server Error: /users/info
Traceback (most recent call last):
  File "C:\Users\Administrator\Envs\django_today\lib\site-packages\django\core\handlers\exception.py", line 34, in inner
    response = get_response(request)
  File "C:\Users\Administrator\Envs\django_today\lib\site-packages\django\core\handlers\base.py", line 115, in _get_response
    response = self.process_exception_by_middleware(e, request)
  File "C:\Users\Administrator\Envs\django_today\lib\site-packages\django\core\handlers\base.py", line 113, in _get_response
    response = wrapped_callback(request, *callback_args, **callback_kwargs)
  File "C:\Users\Administrator\Envs\django_today\lib\site-packages\django\views\generic\base.py", line 71, in view
    return self.dispatch(request, *args, **kwargs)
  File "C:\Users\Administrator\Envs\django_today\lib\site-packages\django\views\generic\base.py", line 97, in dispatch
    return handler(request, *args, **kwargs)
  File "D:\Django_today\my_fresh\apps\users\views.py", line 200, in get
    return render(request, 'user_center_info.html')
  File "C:\Users\Administrator\Envs\django_today\lib\site-packages\django\shortcuts.py", line 36, in render
    content = loader.render_to_string(template_name, context, request, using=using)
  File "C:\Users\Administrator\Envs\django_today\lib\site-packages\django\template\loader.py", line 62, in render_to_string
    return template.render(context, request)
  File "C:\Users\Administrator\Envs\django_today\lib\site-packages\django\template\backends\django.py", line 61, in render
    return self.template.render(context)
  File "C:\Users\Administrator\Envs\django_today\lib\site-packages\django\template\base.py", line 171, in render
    return self._render(context)
  File "C:\Users\Administrator\Envs\django_today\lib\site-packages\django\template\base.py", line 163, in _render
    return self.nodelist.render(context)
  File "C:\Users\Administrator\Envs\django_today\lib\site-packages\django\template\base.py", line 937, in render
    bit = node.render_annotated(context)
  File "C:\Users\Administrator\Envs\django_today\lib\site-packages\django\template\base.py", line 904, in render_annotated
    return self.render(context)
  File "C:\Users\Administrator\Envs\django_today\lib\site-packages\django\template\loader_tags.py", line 150, in render
    return compiled_parent._render(context)
  File "C:\Users\Administrator\Envs\django_today\lib\site-packages\django\template\base.py", line 163, in _render
    return self.nodelist.render(context)
  File "C:\Users\Administrator\Envs\django_today\lib\site-packages\django\template\base.py", line 937, in render
    bit = node.render_annotated(context)
  File "C:\Users\Administrator\Envs\django_today\lib\site-packages\django\template\base.py", line 904, in render_annotated
    return self.render(context)
  File "C:\Users\Administrator\Envs\django_today\lib\site-packages\django\template\loader_tags.py", line 150, in render
    return compiled_parent._render(context)
  File "C:\Users\Administrator\Envs\django_today\lib\site-packages\django\template\base.py", line 163, in _render
    return self.nodelist.render(context)
  File "C:\Users\Administrator\Envs\django_today\lib\site-packages\django\template\base.py", line 937, in render
    bit = node.render_annotated(context)
  File "C:\Users\Administrator\Envs\django_today\lib\site-packages\django\template\base.py", line 904, in render_annotated
    return self.render(context)
  File "C:\Users\Administrator\Envs\django_today\lib\site-packages\django\template\loader_tags.py", line 150, in render
    return compiled_parent._render(context)
  File "C:\Users\Administrator\Envs\django_today\lib\site-packages\django\template\base.py", line 163, in _render
    return self.nodelist.render(context)
  File "C:\Users\Administrator\Envs\django_today\lib\site-packages\django\template\base.py", line 937, in render
    bit = node.render_annotated(context)
  File "C:\Users\Administrator\Envs\django_today\lib\site-packages\django\template\base.py", line 904, in render_annotated
    return self.render(context)
  File "C:\Users\Administrator\Envs\django_today\lib\site-packages\django\template\loader_tags.py", line 62, in render
    result = block.nodelist.render(context)
  File "C:\Users\Administrator\Envs\django_today\lib\site-packages\django\template\base.py", line 937, in render
    bit = node.render_annotated(context)
  File "C:\Users\Administrator\Envs\django_today\lib\site-packages\django\template\base.py", line 904, in render_annotated
    return self.render(context)
  File "C:\Users\Administrator\Envs\django_today\lib\site-packages\django\template\defaulttags.py", line 443, in render
    url = reverse(view_name, args=args, kwargs=kwargs, current_app=current_app)
  File "C:\Users\Administrator\Envs\django_today\lib\site-packages\django\urls\base.py", line 90, in reverse
    return iri_to_uri(resolver._reverse_with_prefix(view, prefix, *args, **kwargs))
  File "C:\Users\Administrator\Envs\django_today\lib\site-packages\django\urls\resolvers.py", line 668, in _reverse_with_prefix
    raise NoReverseMatch(msg)
django.urls.exceptions.NoReverseMatch: Reverse for 'user' not found. 'user' is not a valid view function or pattern name.
2020-06-22 03:39:01,729 - autoreload.py[line:203] - INFO: D:\Django_today\my_fresh\my_fresh\settings.py changed, reloading.
2020-06-22 04:25:14,443 - autoreload.py[line:203] - INFO: D:\Django_today\my_fresh\apps\users\views.py changed, reloading.
2020-06-22 05:02:33,226 - log.py[line:222] - ERROR: Internal Server Error: /users/address
Traceback (most recent call last):
  File "C:\Users\Administrator\Envs\django_today\lib\site-packages\django\db\backends\utils.py", line 84, in _execute
    return self.cursor.execute(sql, params)
  File "C:\Users\Administrator\Envs\django_today\lib\site-packages\django\db\backends\mysql\base.py", line 71, in execute
    return self.cursor.execute(query, args)
  File "C:\Users\Administrator\Envs\django_today\lib\site-packages\pymysql\cursors.py", line 170, in execute
    result = self._query(query)
  File "C:\Users\Administrator\Envs\django_today\lib\site-packages\pymysql\cursors.py", line 328, in _query
    conn.query(q)
  File "C:\Users\Administrator\Envs\django_today\lib\site-packages\pymysql\connections.py", line 517, in query
    self._affected_rows = self._read_query_result(unbuffered=unbuffered)
  File "C:\Users\Administrator\Envs\django_today\lib\site-packages\pymysql\connections.py", line 732, in _read_query_result
    result.read()
  File "C:\Users\Administrator\Envs\django_today\lib\site-packages\pymysql\connections.py", line 1075, in read
    first_packet = self.connection._read_packet()
  File "C:\Users\Administrator\Envs\django_today\lib\site-packages\pymysql\connections.py", line 684, in _read_packet
    packet.check_error()
  File "C:\Users\Administrator\Envs\django_today\lib\site-packages\pymysql\protocol.py", line 220, in check_error
    err.raise_mysql_exception(self._data)
  File "C:\Users\Administrator\Envs\django_today\lib\site-packages\pymysql\err.py", line 109, in raise_mysql_exception
    raise errorclass(errno, errval)
pymysql.err.IntegrityError: (1048, "Column 'addr' cannot be null")

The above exception was the direct cause of the following exception:

Traceback (most recent call last):
  File "C:\Users\Administrator\Envs\django_today\lib\site-packages\django\core\handlers\exception.py", line 34, in inner
    response = get_response(request)
  File "C:\Users\Administrator\Envs\django_today\lib\site-packages\django\core\handlers\base.py", line 115, in _get_response
    response = self.process_exception_by_middleware(e, request)
  File "C:\Users\Administrator\Envs\django_today\lib\site-packages\django\core\handlers\base.py", line 113, in _get_response
    response = wrapped_callback(request, *callback_args, **callback_kwargs)
  File "C:\Users\Administrator\Envs\django_today\lib\site-packages\django\contrib\auth\decorators.py", line 21, in _wrapped_view
    return view_func(request, *args, **kwargs)
  File "C:\Users\Administrator\Envs\django_today\lib\site-packages\django\contrib\auth\decorators.py", line 21, in _wrapped_view
    return view_func(request, *args, **kwargs)
  File "C:\Users\Administrator\Envs\django_today\lib\site-packages\django\views\generic\base.py", line 71, in view
    return self.dispatch(request, *args, **kwargs)
  File "C:\Users\Administrator\Envs\django_today\lib\site-packages\django\views\generic\base.py", line 97, in dispatch
    return handler(request, *args, **kwargs)
  File "D:\Django_today\my_fresh\apps\users\views.py", line 261, in post
    Address.objects.create(user=user,
  File "C:\Users\Administrator\Envs\django_today\lib\site-packages\django\db\models\manager.py", line 82, in manager_method
    return getattr(self.get_queryset(), name)(*args, **kwargs)
  File "C:\Users\Administrator\Envs\django_today\lib\site-packages\django\db\models\query.py", line 422, in create
    obj.save(force_insert=True, using=self.db)
  File "C:\Users\Administrator\Envs\django_today\lib\site-packages\django\db\models\base.py", line 740, in save
    self.save_base(using=using, force_insert=force_insert,
  File "C:\Users\Administrator\Envs\django_today\lib\site-packages\django\db\models\base.py", line 777, in save_base
    updated = self._save_table(
  File "C:\Users\Administrator\Envs\django_today\lib\site-packages\django\db\models\base.py", line 870, in _save_table
    result = self._do_insert(cls._base_manager, using, fields, update_pk, raw)
  File "C:\Users\Administrator\Envs\django_today\lib\site-packages\django\db\models\base.py", line 907, in _do_insert
    return manager._insert([self], fields=fields, return_id=update_pk,
  File "C:\Users\Administrator\Envs\django_today\lib\site-packages\django\db\models\manager.py", line 82, in manager_method
    return getattr(self.get_queryset(), name)(*args, **kwargs)
  File "C:\Users\Administrator\Envs\django_today\lib\site-packages\django\db\models\query.py", line 1186, in _insert
    return query.get_compiler(using=using).execute_sql(return_id)
  File "C:\Users\Administrator\Envs\django_today\lib\site-packages\django\db\models\sql\compiler.py", line 1335, in execute_sql
    cursor.execute(sql, params)
  File "C:\Users\Administrator\Envs\django_today\lib\site-packages\django\db\backends\utils.py", line 99, in execute
    return super().execute(sql, params)
  File "C:\Users\Administrator\Envs\django_today\lib\site-packages\django\db\backends\utils.py", line 67, in execute
    return self._execute_with_wrappers(sql, params, many=False, executor=self._execute)
  File "C:\Users\Administrator\Envs\django_today\lib\site-packages\django\db\backends\utils.py", line 76, in _execute_with_wrappers
    return executor(sql, params, many, context)
  File "C:\Users\Administrator\Envs\django_today\lib\site-packages\django\db\backends\utils.py", line 84, in _execute
    return self.cursor.execute(sql, params)
  File "C:\Users\Administrator\Envs\django_today\lib\site-packages\django\db\utils.py", line 89, in __exit__
    raise dj_exc_value.with_traceback(traceback) from exc_value
  File "C:\Users\Administrator\Envs\django_today\lib\site-packages\django\db\backends\utils.py", line 84, in _execute
    return self.cursor.execute(sql, params)
  File "C:\Users\Administrator\Envs\django_today\lib\site-packages\django\db\backends\mysql\base.py", line 71, in execute
    return self.cursor.execute(query, args)
  File "C:\Users\Administrator\Envs\django_today\lib\site-packages\pymysql\cursors.py", line 170, in execute
    result = self._query(query)
  File "C:\Users\Administrator\Envs\django_today\lib\site-packages\pymysql\cursors.py", line 328, in _query
    conn.query(q)
  File "C:\Users\Administrator\Envs\django_today\lib\site-packages\pymysql\connections.py", line 517, in query
    self._affected_rows = self._read_query_result(unbuffered=unbuffered)
  File "C:\Users\Administrator\Envs\django_today\lib\site-packages\pymysql\connections.py", line 732, in _read_query_result
    result.read()
  File "C:\Users\Administrator\Envs\django_today\lib\site-packages\pymysql\connections.py", line 1075, in read
    first_packet = self.connection._read_packet()
  File "C:\Users\Administrator\Envs\django_today\lib\site-packages\pymysql\connections.py", line 684, in _read_packet
    packet.check_error()
  File "C:\Users\Administrator\Envs\django_today\lib\site-packages\pymysql\protocol.py", line 220, in check_error
    err.raise_mysql_exception(self._data)
  File "C:\Users\Administrator\Envs\django_today\lib\site-packages\pymysql\err.py", line 109, in raise_mysql_exception
    raise errorclass(errno, errval)
django.db.utils.IntegrityError: (1048, "Column 'addr' cannot be null")
2020-06-22 05:13:41,601 - autoreload.py[line:203] - INFO: D:\Django_today\my_fresh\apps\users\views.py changed, reloading.
2020-06-22 06:43:01,090 - connectionpool.py[line:937] - DEBUG: Starting new HTTPS connection (1): uc.qbox.me:443
2020-06-22 06:43:01,256 - connectionpool.py[line:433] - DEBUG: https://uc.qbox.me:443 "GET /v1/query?ak=LfXjXvG1e6vPXV2UFLfXrJ14uNM792vqONhnLyB2&bucket=flask-ihome-python65 HTTP/1.1" 200 486
2020-06-22 06:43:01,258 - retry.py[line:230] - DEBUG: Converted retries value: 3 -> Retry(total=3, connect=None, read=None, redirect=None, status=None)
2020-06-22 06:43:01,261 - connectionpool.py[line:226] - DEBUG: Starting new HTTP connection (1): up.qiniu.com:80
2020-06-22 06:43:01,582 - connectionpool.py[line:433] - DEBUG: http://up.qiniu.com:80 "POST / HTTP/1.1" 200 76
2020-06-22 06:47:55,261 - autoreload.py[line:203] - INFO: D:\Django_today\my_fresh\utils\updown_image\cloudy_img.py changed, reloading.
